[2025-01-28T23:46:51.689+0000] {local_task_job_runner.py:123} INFO - ::group::Pre task execution logs
[2025-01-28T23:46:51.716+0000] {taskinstance.py:2612} INFO - Dependencies all met for dep_context=non-requeueable deps ti=<TaskInstance: pull_gazettes_data.generate_indexes_task scheduled__2025-01-27T00:00:00+00:00 [queued]>
[2025-01-28T23:46:51.730+0000] {taskinstance.py:2612} INFO - Dependencies all met for dep_context=requeueable deps ti=<TaskInstance: pull_gazettes_data.generate_indexes_task scheduled__2025-01-27T00:00:00+00:00 [queued]>
[2025-01-28T23:46:51.732+0000] {taskinstance.py:2865} INFO - Starting attempt 7 of 8
[2025-01-28T23:46:51.750+0000] {taskinstance.py:2888} INFO - Executing <Task(GenerateIndexTask): generate_indexes_task> on 2025-01-27 00:00:00+00:00
[2025-01-28T23:46:51.764+0000] {warnings.py:112} WARNING - /home/***/.local/lib/python3.12/site-packages/***/task/task_runner/standard_task_runner.py:70: DeprecationWarning: This process (pid=3368) is multi-threaded, use of fork() may lead to deadlocks in the child.
  pid = os.fork()

[2025-01-28T23:46:51.766+0000] {standard_task_runner.py:72} INFO - Started process 3370 to run task
[2025-01-28T23:46:51.767+0000] {standard_task_runner.py:104} INFO - Running: ['***', 'tasks', 'run', 'pull_gazettes_data', 'generate_indexes_task', 'scheduled__2025-01-27T00:00:00+00:00', '--job-id', '263', '--raw', '--subdir', 'DAGS_FOLDER/dag_script.py', '--cfg-path', '/tmp/tmpc1lln28z']
[2025-01-28T23:46:51.774+0000] {standard_task_runner.py:105} INFO - Job 263: Subtask generate_indexes_task
[2025-01-28T23:46:51.834+0000] {task_command.py:467} INFO - Running <TaskInstance: pull_gazettes_data.generate_indexes_task scheduled__2025-01-27T00:00:00+00:00 [running]> on host 41bcec3d818b
[2025-01-28T23:46:51.922+0000] {taskinstance.py:3131} INFO - Exporting env vars: AIRFLOW_CTX_DAG_EMAIL='***@example.com' AIRFLOW_CTX_DAG_OWNER='***' AIRFLOW_CTX_DAG_ID='pull_gazettes_data' AIRFLOW_CTX_TASK_ID='generate_indexes_task' AIRFLOW_CTX_EXECUTION_DATE='2025-01-27T00:00:00+00:00' AIRFLOW_CTX_TRY_NUMBER='7' AIRFLOW_CTX_DAG_RUN_ID='scheduled__2025-01-27T00:00:00+00:00'
[2025-01-28T23:46:51.924+0000] {taskinstance.py:731} INFO - ::endgroup::
[2025-01-28T23:46:51.940+0000] {logging_mixin.py:190} INFO - Initializing database
[2025-01-28T23:46:52.491+0000] {_client.py:1026} INFO - HTTP Request: POST https://stg.api.cohere.ai/v1/embed "HTTP/1.1 200 OK"
[2025-01-28T23:46:52.522+0000] {logging_mixin.py:190} INFO - Parsing database current state
[2025-01-28T23:46:52.524+0000] {logging_mixin.py:190} INFO - instantiating new database /usr/local/***/data/vector_db/
[2025-01-28T23:46:52.525+0000] {logging_mixin.py:190} INFO - Reading file metadata
[2025-01-28T23:46:52.527+0000] {taskinstance.py:3310} ERROR - Task failed with exception
Traceback (most recent call last):
  File "/home/airflow/.local/lib/python3.12/site-packages/airflow/models/taskinstance.py", line 767, in _execute_task
    result = _execute_callable(context=context, **execute_callable_kwargs)
             ^^^^^^^^^^^^^^^^^^^^^^^^^^^^^^^^^^^^^^^^^^^^^^^^^^^^^^^^^^^^^
  File "/home/airflow/.local/lib/python3.12/site-packages/airflow/models/taskinstance.py", line 733, in _execute_callable
    return ExecutionCallableRunner(
           ^^^^^^^^^^^^^^^^^^^^^^^^
  File "/home/airflow/.local/lib/python3.12/site-packages/airflow/utils/operator_helpers.py", line 252, in run
    return self.func(*args, **kwargs)
           ^^^^^^^^^^^^^^^^^^^^^^^^^^
  File "/home/airflow/.local/lib/python3.12/site-packages/airflow/models/baseoperator.py", line 406, in wrapper
    return func(self, *args, **kwargs)
           ^^^^^^^^^^^^^^^^^^^^^^^^^^^
  File "/opt/airflow/dags/utils/generate_index_task.py", line 208, in execute
    file_metadata_list = self.init_file_metadata()
                         ^^^^^^^^^^^^^^^^^^^^^^^^^
  File "/opt/airflow/dags/utils/generate_index_task.py", line 77, in init_file_metadata
    metadata = pd.read_csv(self.metadata_path)
               ^^^^^^^^^^^^^^^^^^^^^^^^^^^^^^^
  File "/home/airflow/.local/lib/python3.12/site-packages/pandas/io/parsers/readers.py", line 948, in read_csv
    return _read(filepath_or_buffer, kwds)
           ^^^^^^^^^^^^^^^^^^^^^^^^^^^^^^^
  File "/home/airflow/.local/lib/python3.12/site-packages/pandas/io/parsers/readers.py", line 611, in _read
    parser = TextFileReader(filepath_or_buffer, **kwds)
             ^^^^^^^^^^^^^^^^^^^^^^^^^^^^^^^^^^^^^^^^^^
  File "/home/airflow/.local/lib/python3.12/site-packages/pandas/io/parsers/readers.py", line 1448, in __init__
    self._engine = self._make_engine(f, self.engine)
                   ^^^^^^^^^^^^^^^^^^^^^^^^^^^^^^^^^
  File "/home/airflow/.local/lib/python3.12/site-packages/pandas/io/parsers/readers.py", line 1705, in _make_engine
    self.handles = get_handle(
                   ^^^^^^^^^^^
  File "/home/airflow/.local/lib/python3.12/site-packages/pandas/io/common.py", line 863, in get_handle
    handle = open(
             ^^^^^
FileNotFoundError: [Errno 2] No such file or directory: '/usr/local/airflow/data/ingestion_checkpoint_logs/preprocessed_documents_log.csv'
[2025-01-28T23:46:52.552+0000] {taskinstance.py:1225} INFO - Marking task as UP_FOR_RETRY. dag_id=pull_gazettes_data, task_id=generate_indexes_task, run_id=scheduled__2025-01-27T00:00:00+00:00, execution_date=20250127T000000, start_date=20250128T234651, end_date=20250128T234652
[2025-01-28T23:46:52.571+0000] {taskinstance.py:340} INFO - ::group::Post task execution logs
[2025-01-28T23:46:52.572+0000] {standard_task_runner.py:124} ERROR - Failed to execute job 263 for task generate_indexes_task ([Errno 2] No such file or directory: '/usr/local/airflow/data/ingestion_checkpoint_logs/preprocessed_documents_log.csv'; 3370)
Traceback (most recent call last):
  File "/home/airflow/.local/lib/python3.12/site-packages/airflow/task/task_runner/standard_task_runner.py", line 117, in _start_by_fork
    ret = args.func(args, dag=self.dag)
          ^^^^^^^^^^^^^^^^^^^^^^^^^^^^^
  File "/home/airflow/.local/lib/python3.12/site-packages/airflow/cli/cli_config.py", line 49, in command
    return func(*args, **kwargs)
           ^^^^^^^^^^^^^^^^^^^^^
  File "/home/airflow/.local/lib/python3.12/site-packages/airflow/utils/cli.py", line 115, in wrapper
    return f(*args, **kwargs)
           ^^^^^^^^^^^^^^^^^^
  File "/home/airflow/.local/lib/python3.12/site-packages/airflow/cli/commands/task_command.py", line 483, in task_run
    task_return_code = _run_task_by_selected_method(args, _dag, ti)
                       ^^^^^^^^^^^^^^^^^^^^^^^^^^^^^^^^^^^^^^^^^^^^
  File "/home/airflow/.local/lib/python3.12/site-packages/airflow/cli/commands/task_command.py", line 256, in _run_task_by_selected_method
    return _run_raw_task(args, ti)
           ^^^^^^^^^^^^^^^^^^^^^^^
  File "/home/airflow/.local/lib/python3.12/site-packages/airflow/cli/commands/task_command.py", line 341, in _run_raw_task
    return ti._run_raw_task(
           ^^^^^^^^^^^^^^^^^
  File "/home/airflow/.local/lib/python3.12/site-packages/airflow/utils/session.py", line 97, in wrapper
    return func(*args, session=session, **kwargs)
           ^^^^^^^^^^^^^^^^^^^^^^^^^^^^^^^^^^^^^^
  File "/home/airflow/.local/lib/python3.12/site-packages/airflow/models/taskinstance.py", line 3004, in _run_raw_task
    return _run_raw_task(
           ^^^^^^^^^^^^^^
  File "/home/airflow/.local/lib/python3.12/site-packages/airflow/models/taskinstance.py", line 273, in _run_raw_task
    TaskInstance._execute_task_with_callbacks(
  File "/home/airflow/.local/lib/python3.12/site-packages/airflow/models/taskinstance.py", line 3158, in _execute_task_with_callbacks
    result = self._execute_task(context, task_orig)
             ^^^^^^^^^^^^^^^^^^^^^^^^^^^^^^^^^^^^^^
  File "/home/airflow/.local/lib/python3.12/site-packages/airflow/models/taskinstance.py", line 3182, in _execute_task
    return _execute_task(self, context, task_orig)
           ^^^^^^^^^^^^^^^^^^^^^^^^^^^^^^^^^^^^^^^
  File "/home/airflow/.local/lib/python3.12/site-packages/airflow/models/taskinstance.py", line 767, in _execute_task
    result = _execute_callable(context=context, **execute_callable_kwargs)
             ^^^^^^^^^^^^^^^^^^^^^^^^^^^^^^^^^^^^^^^^^^^^^^^^^^^^^^^^^^^^^
  File "/home/airflow/.local/lib/python3.12/site-packages/airflow/models/taskinstance.py", line 733, in _execute_callable
    return ExecutionCallableRunner(
           ^^^^^^^^^^^^^^^^^^^^^^^^
  File "/home/airflow/.local/lib/python3.12/site-packages/airflow/utils/operator_helpers.py", line 252, in run
    return self.func(*args, **kwargs)
           ^^^^^^^^^^^^^^^^^^^^^^^^^^
  File "/home/airflow/.local/lib/python3.12/site-packages/airflow/models/baseoperator.py", line 406, in wrapper
    return func(self, *args, **kwargs)
           ^^^^^^^^^^^^^^^^^^^^^^^^^^^
  File "/opt/airflow/dags/utils/generate_index_task.py", line 208, in execute
    file_metadata_list = self.init_file_metadata()
                         ^^^^^^^^^^^^^^^^^^^^^^^^^
  File "/opt/airflow/dags/utils/generate_index_task.py", line 77, in init_file_metadata
    metadata = pd.read_csv(self.metadata_path)
               ^^^^^^^^^^^^^^^^^^^^^^^^^^^^^^^
  File "/home/airflow/.local/lib/python3.12/site-packages/pandas/io/parsers/readers.py", line 948, in read_csv
    return _read(filepath_or_buffer, kwds)
           ^^^^^^^^^^^^^^^^^^^^^^^^^^^^^^^
  File "/home/airflow/.local/lib/python3.12/site-packages/pandas/io/parsers/readers.py", line 611, in _read
    parser = TextFileReader(filepath_or_buffer, **kwds)
             ^^^^^^^^^^^^^^^^^^^^^^^^^^^^^^^^^^^^^^^^^^
  File "/home/airflow/.local/lib/python3.12/site-packages/pandas/io/parsers/readers.py", line 1448, in __init__
    self._engine = self._make_engine(f, self.engine)
                   ^^^^^^^^^^^^^^^^^^^^^^^^^^^^^^^^^
  File "/home/airflow/.local/lib/python3.12/site-packages/pandas/io/parsers/readers.py", line 1705, in _make_engine
    self.handles = get_handle(
                   ^^^^^^^^^^^
  File "/home/airflow/.local/lib/python3.12/site-packages/pandas/io/common.py", line 863, in get_handle
    handle = open(
             ^^^^^
FileNotFoundError: [Errno 2] No such file or directory: '/usr/local/airflow/data/ingestion_checkpoint_logs/preprocessed_documents_log.csv'
[2025-01-28T23:46:52.626+0000] {local_task_job_runner.py:266} INFO - Task exited with return code 1
[2025-01-28T23:46:52.653+0000] {taskinstance.py:3900} INFO - 0 downstream tasks scheduled from follow-on schedule check
[2025-01-28T23:46:52.655+0000] {local_task_job_runner.py:245} INFO - ::endgroup::
