[2025-01-25T20:43:29.549+0000] {local_task_job_runner.py:123} INFO - ::group::Pre task execution logs
[2025-01-25T20:43:29.564+0000] {taskinstance.py:2612} INFO - Dependencies all met for dep_context=non-requeueable deps ti=<TaskInstance: pull_gazettes_data.download_s3_index_version manual__2025-01-25T20:13:16.586213+00:00 [queued]>
[2025-01-25T20:43:29.572+0000] {taskinstance.py:2612} INFO - Dependencies all met for dep_context=requeueable deps ti=<TaskInstance: pull_gazettes_data.download_s3_index_version manual__2025-01-25T20:13:16.586213+00:00 [queued]>
[2025-01-25T20:43:29.573+0000] {taskinstance.py:2865} INFO - Starting attempt 18 of 19
[2025-01-25T20:43:29.584+0000] {taskinstance.py:2888} INFO - Executing <Task(DownloadContentFromS3): download_s3_index_version> on 2025-01-25 20:13:16.586213+00:00
[2025-01-25T20:43:29.596+0000] {warnings.py:112} WARNING - /home/***/.local/lib/python3.12/site-packages/***/task/task_runner/standard_task_runner.py:70: DeprecationWarning: This process (pid=25972) is multi-threaded, use of fork() may lead to deadlocks in the child.
  pid = os.fork()

[2025-01-25T20:43:29.597+0000] {standard_task_runner.py:72} INFO - Started process 25985 to run task
[2025-01-25T20:43:29.597+0000] {standard_task_runner.py:104} INFO - Running: ['***', 'tasks', 'run', 'pull_gazettes_data', 'download_s3_index_version', 'manual__2025-01-25T20:13:16.586213+00:00', '--job-id', '163', '--raw', '--subdir', 'DAGS_FOLDER/dag_script.py', '--cfg-path', '/tmp/tmpeyzsnuyy']
[2025-01-25T20:43:29.599+0000] {standard_task_runner.py:105} INFO - Job 163: Subtask download_s3_index_version
[2025-01-25T20:43:29.638+0000] {task_command.py:467} INFO - Running <TaskInstance: pull_gazettes_data.download_s3_index_version manual__2025-01-25T20:13:16.586213+00:00 [running]> on host 41bcec3d818b
[2025-01-25T20:43:29.702+0000] {taskinstance.py:3131} INFO - Exporting env vars: AIRFLOW_CTX_DAG_EMAIL='***@example.com' AIRFLOW_CTX_DAG_OWNER='***' AIRFLOW_CTX_DAG_ID='pull_gazettes_data' AIRFLOW_CTX_TASK_ID='download_s3_index_version' AIRFLOW_CTX_EXECUTION_DATE='2025-01-25T20:13:16.586213+00:00' AIRFLOW_CTX_TRY_NUMBER='18' AIRFLOW_CTX_DAG_RUN_ID='manual__2025-01-25T20:13:16.586213+00:00'
[2025-01-25T20:43:29.704+0000] {taskinstance.py:731} INFO - ::endgroup::
[2025-01-25T20:43:29.723+0000] {base.py:84} INFO - Retrieving connection 'minio_s3_conn_id'
[2025-01-25T20:43:29.724+0000] {connection_wrapper.py:391} INFO - AWS Connection (conn_id='minio_s3_conn_id', conn_type='aws') credentials retrieved from extra.
[2025-01-25T20:43:29.725+0000] {warnings.py:112} WARNING - <string>:9: AirflowProviderDeprecationWarning: extra['host'] is deprecated and will be removed in a future release. Please set extra['endpoint_url'] instead

[2025-01-25T20:43:29.923+0000] {s3.py:1422} INFO - Downloading source S3 file from Bucket diario-oficial-db-dump with path vector_db/index.faiss
[2025-01-25T20:43:30.129+0000] {taskinstance.py:3310} ERROR - Task failed with exception
Traceback (most recent call last):
  File "/home/airflow/.local/lib/python3.12/site-packages/airflow/models/taskinstance.py", line 767, in _execute_task
    result = _execute_callable(context=context, **execute_callable_kwargs)
             ^^^^^^^^^^^^^^^^^^^^^^^^^^^^^^^^^^^^^^^^^^^^^^^^^^^^^^^^^^^^^
  File "/home/airflow/.local/lib/python3.12/site-packages/airflow/models/taskinstance.py", line 733, in _execute_callable
    return ExecutionCallableRunner(
           ^^^^^^^^^^^^^^^^^^^^^^^^
  File "/home/airflow/.local/lib/python3.12/site-packages/airflow/utils/operator_helpers.py", line 252, in run
    return self.func(*args, **kwargs)
           ^^^^^^^^^^^^^^^^^^^^^^^^^^
  File "/home/airflow/.local/lib/python3.12/site-packages/airflow/models/baseoperator.py", line 406, in wrapper
    return func(self, *args, **kwargs)
           ^^^^^^^^^^^^^^^^^^^^^^^^^^^
  File "/opt/airflow/dags/utils/download_content_from_s3_bucket.py", line 64, in execute
    self.download_from_s3()
  File "/opt/airflow/dags/utils/download_content_from_s3_bucket.py", line 55, in download_from_s3
    with open(os.path.join(local_file_path, key), 'wb') as f:
         ^^^^^^^^^^^^^^^^^^^^^^^^^^^^^^^^^^^^^^^^^^^^^^
FileNotFoundError: [Errno 2] No such file or directory: '/usr/local/airflow/data/vector_db/vector_db/index.faiss'
[2025-01-25T20:43:30.141+0000] {taskinstance.py:1225} INFO - Marking task as UP_FOR_RETRY. dag_id=pull_gazettes_data, task_id=download_s3_index_version, run_id=manual__2025-01-25T20:13:16.586213+00:00, execution_date=20250125T201316, start_date=20250125T204329, end_date=20250125T204330
[2025-01-25T20:43:30.154+0000] {taskinstance.py:340} INFO - ::group::Post task execution logs
[2025-01-25T20:43:30.154+0000] {standard_task_runner.py:124} ERROR - Failed to execute job 163 for task download_s3_index_version ([Errno 2] No such file or directory: '/usr/local/airflow/data/vector_db/vector_db/index.faiss'; 25985)
Traceback (most recent call last):
  File "/home/airflow/.local/lib/python3.12/site-packages/airflow/task/task_runner/standard_task_runner.py", line 117, in _start_by_fork
    ret = args.func(args, dag=self.dag)
          ^^^^^^^^^^^^^^^^^^^^^^^^^^^^^
  File "/home/airflow/.local/lib/python3.12/site-packages/airflow/cli/cli_config.py", line 49, in command
    return func(*args, **kwargs)
           ^^^^^^^^^^^^^^^^^^^^^
  File "/home/airflow/.local/lib/python3.12/site-packages/airflow/utils/cli.py", line 115, in wrapper
    return f(*args, **kwargs)
           ^^^^^^^^^^^^^^^^^^
  File "/home/airflow/.local/lib/python3.12/site-packages/airflow/cli/commands/task_command.py", line 483, in task_run
    task_return_code = _run_task_by_selected_method(args, _dag, ti)
                       ^^^^^^^^^^^^^^^^^^^^^^^^^^^^^^^^^^^^^^^^^^^^
  File "/home/airflow/.local/lib/python3.12/site-packages/airflow/cli/commands/task_command.py", line 256, in _run_task_by_selected_method
    return _run_raw_task(args, ti)
           ^^^^^^^^^^^^^^^^^^^^^^^
  File "/home/airflow/.local/lib/python3.12/site-packages/airflow/cli/commands/task_command.py", line 341, in _run_raw_task
    return ti._run_raw_task(
           ^^^^^^^^^^^^^^^^^
  File "/home/airflow/.local/lib/python3.12/site-packages/airflow/utils/session.py", line 97, in wrapper
    return func(*args, session=session, **kwargs)
           ^^^^^^^^^^^^^^^^^^^^^^^^^^^^^^^^^^^^^^
  File "/home/airflow/.local/lib/python3.12/site-packages/airflow/models/taskinstance.py", line 3004, in _run_raw_task
    return _run_raw_task(
           ^^^^^^^^^^^^^^
  File "/home/airflow/.local/lib/python3.12/site-packages/airflow/models/taskinstance.py", line 273, in _run_raw_task
    TaskInstance._execute_task_with_callbacks(
  File "/home/airflow/.local/lib/python3.12/site-packages/airflow/models/taskinstance.py", line 3158, in _execute_task_with_callbacks
    result = self._execute_task(context, task_orig)
             ^^^^^^^^^^^^^^^^^^^^^^^^^^^^^^^^^^^^^^
  File "/home/airflow/.local/lib/python3.12/site-packages/airflow/models/taskinstance.py", line 3182, in _execute_task
    return _execute_task(self, context, task_orig)
           ^^^^^^^^^^^^^^^^^^^^^^^^^^^^^^^^^^^^^^^
  File "/home/airflow/.local/lib/python3.12/site-packages/airflow/models/taskinstance.py", line 767, in _execute_task
    result = _execute_callable(context=context, **execute_callable_kwargs)
             ^^^^^^^^^^^^^^^^^^^^^^^^^^^^^^^^^^^^^^^^^^^^^^^^^^^^^^^^^^^^^
  File "/home/airflow/.local/lib/python3.12/site-packages/airflow/models/taskinstance.py", line 733, in _execute_callable
    return ExecutionCallableRunner(
           ^^^^^^^^^^^^^^^^^^^^^^^^
  File "/home/airflow/.local/lib/python3.12/site-packages/airflow/utils/operator_helpers.py", line 252, in run
    return self.func(*args, **kwargs)
           ^^^^^^^^^^^^^^^^^^^^^^^^^^
  File "/home/airflow/.local/lib/python3.12/site-packages/airflow/models/baseoperator.py", line 406, in wrapper
    return func(self, *args, **kwargs)
           ^^^^^^^^^^^^^^^^^^^^^^^^^^^
  File "/opt/airflow/dags/utils/download_content_from_s3_bucket.py", line 64, in execute
    self.download_from_s3()
  File "/opt/airflow/dags/utils/download_content_from_s3_bucket.py", line 55, in download_from_s3
    with open(os.path.join(local_file_path, key), 'wb') as f:
         ^^^^^^^^^^^^^^^^^^^^^^^^^^^^^^^^^^^^^^^^^^^^^^
FileNotFoundError: [Errno 2] No such file or directory: '/usr/local/airflow/data/vector_db/vector_db/index.faiss'
[2025-01-25T20:43:30.174+0000] {local_task_job_runner.py:266} INFO - Task exited with return code 1
[2025-01-25T20:43:30.188+0000] {local_task_job_runner.py:245} INFO - ::endgroup::
