[2025-01-25T20:38:18.136+0000] {local_task_job_runner.py:123} INFO - ::group::Pre task execution logs
[2025-01-25T20:38:18.150+0000] {taskinstance.py:2612} INFO - Dependencies all met for dep_context=non-requeueable deps ti=<TaskInstance: pull_gazettes_data.download_s3_index_version manual__2025-01-25T20:13:16.586213+00:00 [queued]>
[2025-01-25T20:38:18.158+0000] {taskinstance.py:2612} INFO - Dependencies all met for dep_context=requeueable deps ti=<TaskInstance: pull_gazettes_data.download_s3_index_version manual__2025-01-25T20:13:16.586213+00:00 [queued]>
[2025-01-25T20:38:18.159+0000] {taskinstance.py:2865} INFO - Starting attempt 16 of 17
[2025-01-25T20:38:18.171+0000] {taskinstance.py:2888} INFO - Executing <Task(DownloadContentFromS3): download_s3_index_version> on 2025-01-25 20:13:16.586213+00:00
[2025-01-25T20:38:18.182+0000] {warnings.py:112} WARNING - /home/***/.local/lib/python3.12/site-packages/***/task/task_runner/standard_task_runner.py:70: DeprecationWarning: This process (pid=25774) is multi-threaded, use of fork() may lead to deadlocks in the child.
  pid = os.fork()

[2025-01-25T20:38:18.184+0000] {standard_task_runner.py:72} INFO - Started process 25787 to run task
[2025-01-25T20:38:18.184+0000] {standard_task_runner.py:104} INFO - Running: ['***', 'tasks', 'run', 'pull_gazettes_data', 'download_s3_index_version', 'manual__2025-01-25T20:13:16.586213+00:00', '--job-id', '161', '--raw', '--subdir', 'DAGS_FOLDER/dag_script.py', '--cfg-path', '/tmp/tmpj4yzrz8p']
[2025-01-25T20:38:18.188+0000] {standard_task_runner.py:105} INFO - Job 161: Subtask download_s3_index_version
[2025-01-25T20:38:18.227+0000] {task_command.py:467} INFO - Running <TaskInstance: pull_gazettes_data.download_s3_index_version manual__2025-01-25T20:13:16.586213+00:00 [running]> on host 41bcec3d818b
[2025-01-25T20:38:18.291+0000] {taskinstance.py:3131} INFO - Exporting env vars: AIRFLOW_CTX_DAG_EMAIL='***@example.com' AIRFLOW_CTX_DAG_OWNER='***' AIRFLOW_CTX_DAG_ID='pull_gazettes_data' AIRFLOW_CTX_TASK_ID='download_s3_index_version' AIRFLOW_CTX_EXECUTION_DATE='2025-01-25T20:13:16.586213+00:00' AIRFLOW_CTX_TRY_NUMBER='16' AIRFLOW_CTX_DAG_RUN_ID='manual__2025-01-25T20:13:16.586213+00:00'
[2025-01-25T20:38:18.293+0000] {taskinstance.py:731} INFO - ::endgroup::
[2025-01-25T20:38:18.311+0000] {base.py:84} INFO - Retrieving connection 'minio_s3_conn_id'
[2025-01-25T20:38:18.312+0000] {connection_wrapper.py:391} INFO - AWS Connection (conn_id='minio_s3_conn_id', conn_type='aws') credentials retrieved from extra.
[2025-01-25T20:38:18.313+0000] {warnings.py:112} WARNING - <string>:9: AirflowProviderDeprecationWarning: extra['host'] is deprecated and will be removed in a future release. Please set extra['endpoint_url'] instead

[2025-01-25T20:38:18.527+0000] {s3.py:1422} INFO - Downloading source S3 file from Bucket diario-oficial-db-dump with path vector_db/index.faiss
[2025-01-25T20:38:58.582+0000] {local_task_job_runner.py:346} WARNING - State of this instance has been externally set to restarting. Terminating instance.
[2025-01-25T20:38:58.584+0000] {local_task_job_runner.py:245} INFO - ::endgroup::
[2025-01-25T20:38:58.585+0000] {process_utils.py:132} INFO - Sending 15 to group 25787. PIDs of all processes in the group: [25787]
[2025-01-25T20:38:58.585+0000] {process_utils.py:87} INFO - Sending the signal 15 to group 25787
[2025-01-25T20:38:58.586+0000] {taskinstance.py:3092} ERROR - Received SIGTERM. Terminating subprocesses.
[2025-01-25T20:38:58.596+0000] {taskinstance.py:3310} ERROR - Task failed with exception
Traceback (most recent call last):
  File "/usr/local/lib/python3.12/shutil.py", line 847, in move
    os.rename(src, real_dst)
FileNotFoundError: [Errno 2] No such file or directory: '/usr/local/airflow/data/vector_db/airflow_tmp_dir_30329e40/index.faiss' -> '/usr/local/airflow/data/vector_db/vector_db/index.faiss'

During handling of the above exception, another exception occurred:

Traceback (most recent call last):
  File "/opt/airflow/dags/utils/download_content_from_s3_bucket.py", line 55, in download_from_s3
    shutil.move(filename,os.path.join(local_file_path, key))
  File "/usr/local/lib/python3.12/shutil.py", line 867, in move
    copy_function(src, real_dst)
  File "/usr/local/lib/python3.12/shutil.py", line 475, in copy2
    copyfile(src, dst, follow_symlinks=follow_symlinks)
  File "/usr/local/lib/python3.12/shutil.py", line 262, in copyfile
    with open(dst, 'wb') as fdst:
         ^^^^^^^^^^^^^^^
FileNotFoundError: [Errno 2] No such file or directory: '/usr/local/airflow/data/vector_db/vector_db/index.faiss'

During handling of the above exception, another exception occurred:

Traceback (most recent call last):
  File "/home/airflow/.local/lib/python3.12/site-packages/airflow/models/taskinstance.py", line 767, in _execute_task
    result = _execute_callable(context=context, **execute_callable_kwargs)
             ^^^^^^^^^^^^^^^^^^^^^^^^^^^^^^^^^^^^^^^^^^^^^^^^^^^^^^^^^^^^^
  File "/home/airflow/.local/lib/python3.12/site-packages/airflow/models/taskinstance.py", line 733, in _execute_callable
    return ExecutionCallableRunner(
           ^^^^^^^^^^^^^^^^^^^^^^^^
  File "/home/airflow/.local/lib/python3.12/site-packages/airflow/utils/operator_helpers.py", line 252, in run
    return self.func(*args, **kwargs)
           ^^^^^^^^^^^^^^^^^^^^^^^^^^
  File "/home/airflow/.local/lib/python3.12/site-packages/airflow/models/baseoperator.py", line 406, in wrapper
    return func(self, *args, **kwargs)
           ^^^^^^^^^^^^^^^^^^^^^^^^^^^
  File "/opt/airflow/dags/utils/download_content_from_s3_bucket.py", line 66, in execute
    if self.s3_bucket_exists():
        ^^^^^^^^^^^^^^^^^^^^^^^
  File "/opt/airflow/dags/utils/download_content_from_s3_bucket.py", line 59, in download_from_s3
    print(e)
  File "/home/airflow/.local/lib/python3.12/site-packages/airflow/models/taskinstance.py", line 3094, in signal_handler
    raise AirflowTaskTerminated("Task received SIGTERM signal")
airflow.exceptions.AirflowTaskTerminated: Task received SIGTERM signal
[2025-01-25T20:38:58.607+0000] {taskinstance.py:1225} INFO - Marking task as UP_FOR_RETRY. dag_id=pull_gazettes_data, task_id=download_s3_index_version, run_id=manual__2025-01-25T20:13:16.586213+00:00, execution_date=20250125T201316, start_date=20250125T203818, end_date=20250125T203858
[2025-01-25T20:38:58.618+0000] {taskinstance.py:340} INFO - ::group::Post task execution logs
[2025-01-25T20:38:58.638+0000] {process_utils.py:80} INFO - Process psutil.Process(pid=25787, status='terminated', exitcode=2, started='20:38:17') (25787) terminated with exit code 2
