[2025-01-25T16:01:55.326+0000] {local_task_job_runner.py:123} INFO - ::group::Pre task execution logs
[2025-01-25T16:01:55.342+0000] {taskinstance.py:2612} INFO - Dependencies all met for dep_context=non-requeueable deps ti=<TaskInstance: pull_gazettes_data.generate_indexes_task scheduled__2025-01-24T00:00:00+00:00 [queued]>
[2025-01-25T16:01:55.351+0000] {taskinstance.py:2612} INFO - Dependencies all met for dep_context=requeueable deps ti=<TaskInstance: pull_gazettes_data.generate_indexes_task scheduled__2025-01-24T00:00:00+00:00 [queued]>
[2025-01-25T16:01:55.351+0000] {taskinstance.py:2865} INFO - Starting attempt 10 of 11
[2025-01-25T16:01:55.364+0000] {taskinstance.py:2888} INFO - Executing <Task(GenerateIndexTask): generate_indexes_task> on 2025-01-24 00:00:00+00:00
[2025-01-25T16:01:55.375+0000] {warnings.py:112} WARNING - /home/***/.local/lib/python3.12/site-packages/***/task/task_runner/standard_task_runner.py:70: DeprecationWarning: This process (pid=14305) is multi-threaded, use of fork() may lead to deadlocks in the child.
  pid = os.fork()

[2025-01-25T16:01:55.377+0000] {standard_task_runner.py:72} INFO - Started process 14318 to run task
[2025-01-25T16:01:55.377+0000] {standard_task_runner.py:104} INFO - Running: ['***', 'tasks', 'run', 'pull_gazettes_data', 'generate_indexes_task', 'scheduled__2025-01-24T00:00:00+00:00', '--job-id', '90', '--raw', '--subdir', 'DAGS_FOLDER/dag_script.py', '--cfg-path', '/tmp/tmpsruejrnr']
[2025-01-25T16:01:55.379+0000] {standard_task_runner.py:105} INFO - Job 90: Subtask generate_indexes_task
[2025-01-25T16:01:55.421+0000] {task_command.py:467} INFO - Running <TaskInstance: pull_gazettes_data.generate_indexes_task scheduled__2025-01-24T00:00:00+00:00 [running]> on host 41bcec3d818b
[2025-01-25T16:01:55.487+0000] {taskinstance.py:3131} INFO - Exporting env vars: AIRFLOW_CTX_DAG_EMAIL='***@example.com' AIRFLOW_CTX_DAG_OWNER='***' AIRFLOW_CTX_DAG_ID='pull_gazettes_data' AIRFLOW_CTX_TASK_ID='generate_indexes_task' AIRFLOW_CTX_EXECUTION_DATE='2025-01-24T00:00:00+00:00' AIRFLOW_CTX_TRY_NUMBER='10' AIRFLOW_CTX_DAG_RUN_ID='scheduled__2025-01-24T00:00:00+00:00'
[2025-01-25T16:01:55.488+0000] {taskinstance.py:731} INFO - ::endgroup::
[2025-01-25T16:01:55.501+0000] {logging_mixin.py:190} INFO - Initializing database
[2025-01-25T16:01:55.942+0000] {_client.py:1026} INFO - HTTP Request: POST https://stg.api.cohere.ai/v1/embed "HTTP/1.1 200 OK"
[2025-01-25T16:01:55.965+0000] {logging_mixin.py:190} INFO - Parsing database current state
[2025-01-25T16:01:55.967+0000] {logging_mixin.py:190} INFO - loading database /usr/local/***/data/vector_db/
[2025-01-25T16:01:55.975+0000] {logging_mixin.py:190} INFO - Reading file metadata
[2025-01-25T16:01:55.983+0000] {taskinstance.py:3310} ERROR - Task failed with exception
Traceback (most recent call last):
  File "/home/airflow/.local/lib/python3.12/site-packages/pandas/core/indexes/base.py", line 3791, in get_loc
    return self._engine.get_loc(casted_key)
           ^^^^^^^^^^^^^^^^^^^^^^^^^^^^^^^^
  File "index.pyx", line 152, in pandas._libs.index.IndexEngine.get_loc
  File "index.pyx", line 181, in pandas._libs.index.IndexEngine.get_loc
  File "pandas/_libs/hashtable_class_helper.pxi", line 7080, in pandas._libs.hashtable.PyObjectHashTable.get_item
  File "pandas/_libs/hashtable_class_helper.pxi", line 7088, in pandas._libs.hashtable.PyObjectHashTable.get_item
KeyError: 'url'

The above exception was the direct cause of the following exception:

Traceback (most recent call last):
  File "/home/airflow/.local/lib/python3.12/site-packages/airflow/models/taskinstance.py", line 767, in _execute_task
    result = _execute_callable(context=context, **execute_callable_kwargs)
             ^^^^^^^^^^^^^^^^^^^^^^^^^^^^^^^^^^^^^^^^^^^^^^^^^^^^^^^^^^^^^
  File "/home/airflow/.local/lib/python3.12/site-packages/airflow/models/taskinstance.py", line 733, in _execute_callable
    return ExecutionCallableRunner(
           ^^^^^^^^^^^^^^^^^^^^^^^^
  File "/home/airflow/.local/lib/python3.12/site-packages/airflow/utils/operator_helpers.py", line 252, in run
    return self.func(*args, **kwargs)
           ^^^^^^^^^^^^^^^^^^^^^^^^^^
  File "/home/airflow/.local/lib/python3.12/site-packages/airflow/models/baseoperator.py", line 406, in wrapper
    return func(self, *args, **kwargs)
           ^^^^^^^^^^^^^^^^^^^^^^^^^^^
  File "/opt/airflow/dags/utils/generate_index_task.py", line 202, in execute
    file_metadata_list = self.init_file_metadata()
                         ^^^^^^^^^^^^^^^^^^^^^^^^^
  File "/opt/airflow/dags/utils/generate_index_task.py", line 82, in init_file_metadata
    url  = file["url"],
          ~~~~^^^^^^^
  File "/home/airflow/.local/lib/python3.12/site-packages/pandas/core/series.py", line 1040, in __getitem__
    return self._get_value(key)
           ^^^^^^^^^^^^^^^^^^^^
  File "/home/airflow/.local/lib/python3.12/site-packages/pandas/core/series.py", line 1156, in _get_value
    loc = self.index.get_loc(label)
          ^^^^^^^^^^^^^^^^^^^^^^^^^
  File "/home/airflow/.local/lib/python3.12/site-packages/pandas/core/indexes/base.py", line 3798, in get_loc
    raise KeyError(key) from err
KeyError: 'url'
[2025-01-25T16:01:56.001+0000] {taskinstance.py:1225} INFO - Marking task as UP_FOR_RETRY. dag_id=pull_gazettes_data, task_id=generate_indexes_task, run_id=scheduled__2025-01-24T00:00:00+00:00, execution_date=20250124T000000, start_date=20250125T160155, end_date=20250125T160156
[2025-01-25T16:01:56.015+0000] {taskinstance.py:340} INFO - ::group::Post task execution logs
[2025-01-25T16:01:56.016+0000] {standard_task_runner.py:124} ERROR - Failed to execute job 90 for task generate_indexes_task ('url'; 14318)
Traceback (most recent call last):
  File "/home/airflow/.local/lib/python3.12/site-packages/pandas/core/indexes/base.py", line 3791, in get_loc
    return self._engine.get_loc(casted_key)
           ^^^^^^^^^^^^^^^^^^^^^^^^^^^^^^^^
  File "index.pyx", line 152, in pandas._libs.index.IndexEngine.get_loc
  File "index.pyx", line 181, in pandas._libs.index.IndexEngine.get_loc
  File "pandas/_libs/hashtable_class_helper.pxi", line 7080, in pandas._libs.hashtable.PyObjectHashTable.get_item
  File "pandas/_libs/hashtable_class_helper.pxi", line 7088, in pandas._libs.hashtable.PyObjectHashTable.get_item
KeyError: 'url'

The above exception was the direct cause of the following exception:

Traceback (most recent call last):
  File "/home/airflow/.local/lib/python3.12/site-packages/airflow/task/task_runner/standard_task_runner.py", line 117, in _start_by_fork
    ret = args.func(args, dag=self.dag)
          ^^^^^^^^^^^^^^^^^^^^^^^^^^^^^
  File "/home/airflow/.local/lib/python3.12/site-packages/airflow/cli/cli_config.py", line 49, in command
    return func(*args, **kwargs)
           ^^^^^^^^^^^^^^^^^^^^^
  File "/home/airflow/.local/lib/python3.12/site-packages/airflow/utils/cli.py", line 115, in wrapper
    return f(*args, **kwargs)
           ^^^^^^^^^^^^^^^^^^
  File "/home/airflow/.local/lib/python3.12/site-packages/airflow/cli/commands/task_command.py", line 483, in task_run
    task_return_code = _run_task_by_selected_method(args, _dag, ti)
                       ^^^^^^^^^^^^^^^^^^^^^^^^^^^^^^^^^^^^^^^^^^^^
  File "/home/airflow/.local/lib/python3.12/site-packages/airflow/cli/commands/task_command.py", line 256, in _run_task_by_selected_method
    return _run_raw_task(args, ti)
           ^^^^^^^^^^^^^^^^^^^^^^^
  File "/home/airflow/.local/lib/python3.12/site-packages/airflow/cli/commands/task_command.py", line 341, in _run_raw_task
    return ti._run_raw_task(
           ^^^^^^^^^^^^^^^^^
  File "/home/airflow/.local/lib/python3.12/site-packages/airflow/utils/session.py", line 97, in wrapper
    return func(*args, session=session, **kwargs)
           ^^^^^^^^^^^^^^^^^^^^^^^^^^^^^^^^^^^^^^
  File "/home/airflow/.local/lib/python3.12/site-packages/airflow/models/taskinstance.py", line 3004, in _run_raw_task
    return _run_raw_task(
           ^^^^^^^^^^^^^^
  File "/home/airflow/.local/lib/python3.12/site-packages/airflow/models/taskinstance.py", line 273, in _run_raw_task
    TaskInstance._execute_task_with_callbacks(
  File "/home/airflow/.local/lib/python3.12/site-packages/airflow/models/taskinstance.py", line 3158, in _execute_task_with_callbacks
    result = self._execute_task(context, task_orig)
             ^^^^^^^^^^^^^^^^^^^^^^^^^^^^^^^^^^^^^^
  File "/home/airflow/.local/lib/python3.12/site-packages/airflow/models/taskinstance.py", line 3182, in _execute_task
    return _execute_task(self, context, task_orig)
           ^^^^^^^^^^^^^^^^^^^^^^^^^^^^^^^^^^^^^^^
  File "/home/airflow/.local/lib/python3.12/site-packages/airflow/models/taskinstance.py", line 767, in _execute_task
    result = _execute_callable(context=context, **execute_callable_kwargs)
             ^^^^^^^^^^^^^^^^^^^^^^^^^^^^^^^^^^^^^^^^^^^^^^^^^^^^^^^^^^^^^
  File "/home/airflow/.local/lib/python3.12/site-packages/airflow/models/taskinstance.py", line 733, in _execute_callable
    return ExecutionCallableRunner(
           ^^^^^^^^^^^^^^^^^^^^^^^^
  File "/home/airflow/.local/lib/python3.12/site-packages/airflow/utils/operator_helpers.py", line 252, in run
    return self.func(*args, **kwargs)
           ^^^^^^^^^^^^^^^^^^^^^^^^^^
  File "/home/airflow/.local/lib/python3.12/site-packages/airflow/models/baseoperator.py", line 406, in wrapper
    return func(self, *args, **kwargs)
           ^^^^^^^^^^^^^^^^^^^^^^^^^^^
  File "/opt/airflow/dags/utils/generate_index_task.py", line 202, in execute
    file_metadata_list = self.init_file_metadata()
                         ^^^^^^^^^^^^^^^^^^^^^^^^^
  File "/opt/airflow/dags/utils/generate_index_task.py", line 82, in init_file_metadata
    url  = file["url"],
          ~~~~^^^^^^^
  File "/home/airflow/.local/lib/python3.12/site-packages/pandas/core/series.py", line 1040, in __getitem__
    return self._get_value(key)
           ^^^^^^^^^^^^^^^^^^^^
  File "/home/airflow/.local/lib/python3.12/site-packages/pandas/core/series.py", line 1156, in _get_value
    loc = self.index.get_loc(label)
          ^^^^^^^^^^^^^^^^^^^^^^^^^
  File "/home/airflow/.local/lib/python3.12/site-packages/pandas/core/indexes/base.py", line 3798, in get_loc
    raise KeyError(key) from err
KeyError: 'url'
[2025-01-25T16:01:56.034+0000] {local_task_job_runner.py:266} INFO - Task exited with return code 1
[2025-01-25T16:01:56.055+0000] {taskinstance.py:3900} INFO - 0 downstream tasks scheduled from follow-on schedule check
[2025-01-25T16:01:56.057+0000] {local_task_job_runner.py:245} INFO - ::endgroup::
